2024-11-03 17:50:36,069 ERROR: Traceback: Traceback (most recent call last):
  File "C:\pinokio\bin\miniconda\envs\munch-meal-planner\lib\site-packages\sqlalchemy\engine\base.py", line 1967, in _exec_single_context
    self.dialect.do_execute(
  File "C:\pinokio\bin\miniconda\envs\munch-meal-planner\lib\site-packages\sqlalchemy\engine\default.py", line 941, in do_execute
    cursor.execute(statement, parameters)
sqlite3.OperationalError: no such table: user

The above exception was the direct cause of the following exception:

Traceback (most recent call last):
  File "c:\Users\kevin\OneDrive\Documents\Code\munch-meal-planner\app\routes.py", line 190, in register
    if form.validate_on_submit():
  File "C:\pinokio\bin\miniconda\envs\munch-meal-planner\lib\site-packages\flask_wtf\form.py", line 86, in validate_on_submit
    return self.is_submitted() and self.validate(extra_validators=extra_validators)
  File "C:\pinokio\bin\miniconda\envs\munch-meal-planner\lib\site-packages\wtforms\form.py", line 329, in validate
    return super().validate(extra)
  File "C:\pinokio\bin\miniconda\envs\munch-meal-planner\lib\site-packages\wtforms\form.py", line 146, in validate
    if not field.validate(self, extra):
  File "C:\pinokio\bin\miniconda\envs\munch-meal-planner\lib\site-packages\wtforms\fields\core.py", line 246, in validate
    stop_validation = self._run_validation_chain(form, chain)
  File "C:\pinokio\bin\miniconda\envs\munch-meal-planner\lib\site-packages\wtforms\fields\core.py", line 266, in _run_validation_chain
    validator(form, self)
  File "c:\Users\kevin\OneDrive\Documents\Code\munch-meal-planner\app\forms.py", line 44, in validate_username
    user = User.query.filter_by(username=username.data).first()
  File "C:\pinokio\bin\miniconda\envs\munch-meal-planner\lib\site-packages\sqlalchemy\orm\query.py", line 2728, in first
    return self.limit(1)._iter().first()  # type: ignore
  File "C:\pinokio\bin\miniconda\envs\munch-meal-planner\lib\site-packages\sqlalchemy\orm\query.py", line 2827, in _iter
    result: Union[ScalarResult[_T], Result[_T]] = self.session.execute(
  File "C:\pinokio\bin\miniconda\envs\munch-meal-planner\lib\site-packages\sqlalchemy\orm\session.py", line 2362, in execute
    return self._execute_internal(
  File "C:\pinokio\bin\miniconda\envs\munch-meal-planner\lib\site-packages\sqlalchemy\orm\session.py", line 2247, in _execute_internal
    result: Result[Any] = compile_state_cls.orm_execute_statement(
  File "C:\pinokio\bin\miniconda\envs\munch-meal-planner\lib\site-packages\sqlalchemy\orm\context.py", line 305, in orm_execute_statement
    result = conn.execute(
  File "C:\pinokio\bin\miniconda\envs\munch-meal-planner\lib\site-packages\sqlalchemy\engine\base.py", line 1418, in execute
    return meth(
  File "C:\pinokio\bin\miniconda\envs\munch-meal-planner\lib\site-packages\sqlalchemy\sql\elements.py", line 515, in _execute_on_connection
    return connection._execute_clauseelement(
  File "C:\pinokio\bin\miniconda\envs\munch-meal-planner\lib\site-packages\sqlalchemy\engine\base.py", line 1640, in _execute_clauseelement
    ret = self._execute_context(
  File "C:\pinokio\bin\miniconda\envs\munch-meal-planner\lib\site-packages\sqlalchemy\engine\base.py", line 1846, in _execute_context
    return self._exec_single_context(
  File "C:\pinokio\bin\miniconda\envs\munch-meal-planner\lib\site-packages\sqlalchemy\engine\base.py", line 1986, in _exec_single_context
    self._handle_dbapi_exception(
  File "C:\pinokio\bin\miniconda\envs\munch-meal-planner\lib\site-packages\sqlalchemy\engine\base.py", line 2355, in _handle_dbapi_exception
    raise sqlalchemy_exception.with_traceback(exc_info[2]) from e
  File "C:\pinokio\bin\miniconda\envs\munch-meal-planner\lib\site-packages\sqlalchemy\engine\base.py", line 1967, in _exec_single_context
    self.dialect.do_execute(
  File "C:\pinokio\bin\miniconda\envs\munch-meal-planner\lib\site-packages\sqlalchemy\engine\default.py", line 941, in do_execute
    cursor.execute(statement, parameters)
sqlalchemy.exc.OperationalError: (sqlite3.OperationalError) no such table: user
[SQL: SELECT user.id AS user_id, user.username AS user_username, user.email AS user_email, user.password_hash AS user_password_hash 
FROM user 
WHERE user.username = ?
 LIMIT ? OFFSET ?]
[parameters: ('Kevin Pesenecker', 1, 0)]
(Background on this error at: https://sqlalche.me/e/20/e3q8)
 [in c:\Users\kevin\OneDrive\Documents\Code\munch-meal-planner\app\routes.py:207]
2024-11-03 17:52:22,121 INFO: Munch startup [in C:\Users\kevin\OneDrive\Documents\Code\munch-meal-planner\app\utils\logger.py:15]
2024-11-03 17:52:38,194 INFO: Munch startup [in C:\Users\kevin\OneDrive\Documents\Code\munch-meal-planner\app\utils\logger.py:15]
2024-11-03 17:52:52,296 INFO: Munch startup [in C:\Users\kevin\OneDrive\Documents\Code\munch-meal-planner\app\utils\logger.py:15]
2024-11-03 17:53:01,191 INFO: Munch startup [in C:\Users\kevin\OneDrive\Documents\Code\munch-meal-planner\app\utils\logger.py:15]
2024-11-03 18:04:41,247 INFO: Munch startup [in c:\Users\kevin\OneDrive\Documents\Code\munch-meal-planner\app\utils\logger.py:15]
2024-11-03 18:05:00,808 INFO: Starting registration process for username: Kevin Pesenecker [in c:\Users\kevin\OneDrive\Documents\Code\munch-meal-planner\app\routes.py:191]
2024-11-03 18:05:00,900 INFO: Successfully registered user: Kevin Pesenecker [in c:\Users\kevin\OneDrive\Documents\Code\munch-meal-planner\app\routes.py:200]
2024-11-03 18:05:05,014 ERROR: Error generating meal suggestion: The api_key client option must be set either by passing api_key to the client or by setting the OPENAI_API_KEY environment variable [in c:\Users\kevin\OneDrive\Documents\Code\munch-meal-planner\app\services\ai_service.py:54]
